<?xml version="1.0"?>
<robot name="bicycle_robot">

  <!-- ───── Links ───── -->
  <link name="world"/>

  <!-- chassis -->
  <link name="base_link">
    <inertial>
      <mass value="1.0"/>
      <origin xyz="0 0 0"/>
      <inertia ixx="0.1" ixy="0" ixz="0" iyy="0.1" iyz="0" izz="0.1"/>
    </inertial>
    <visual>
      <geometry><box size="0.5 0.3 0.1"/></geometry>
      <material name="blue"><color rgba="0.3 0.3 0.7 1"/></material>
    </visual>
    <collision>
      <geometry><box size="0.5 0.3 0.1"/></geometry>
    </collision>
  </link>

  <!-- “virtual” steering body -->
  <link name="steering_link"/>
  <!-- rear wheel (visual only) -->
  <link name="rear_wheel">
    <visual>
      <geometry><cylinder radius="0.1" length="0.05"/></geometry>
      <material name="black"><color rgba="0 0 0 1"/></material>
    </visual>
  </link>
  <!-- front wheel, child of steering link (visual only) -->
  <link name="front_wheel">
    <visual>
      <geometry><cylinder radius="0.1" length="0.05"/></geometry>
      <material name="black"><color rgba="0 0 0 1"/></material>
    </visual>
  </link>

  <!-- ───── Joints ───── -->
  <!-- free-floating base in the world (same as before) -->
  <joint name="floating_base_joint" type="floating">
    <parent link="world"/>
    <child  link="base_link"/>
  </joint>

  <!-- steering (Z rotation) -->
  <joint name="steer_joint" type="continuous">
    <parent link="base_link"/>
    <child  link="steering_link"/>
    <origin xyz="0.25 0 0.05" rpy="0 0 0"/>
    <axis xyz="0 0 1"/>
  </joint>

  <!-- rear wheel fixed to chassis -->
  <joint name="rear_wheel_joint" type="fixed">
    <parent link="base_link"/>
    <child  link="rear_wheel"/>
    <origin xyz="-0.25 0 0" rpy="1.5707 0 0"/>
  </joint>

  <!-- front wheel fixed to the steering link -->
  <joint name="front_wheel_joint" type="fixed">
    <parent link="steering_link"/>
    <child  link="front_wheel"/>
    <origin xyz="0 0 0" rpy="1.5707 0 0"/>
  </joint>

</robot>
